{
    "color": "151525",
    "registryname": "starlight_laser",
    "localizedname": "Starlight Laser",
    "parts": [
        {
            "x": -2,
            "y": 0,
            "z": 2,
            "elements": [
                "thaumicaugmentation:starfield_glass@2"
            ]
        },
        {
            "x": -3,
            "y": 1,
            "z": 3,
            "elements": [
                "astralsorcery:blockblackmarble@2"
            ]
        },
        {
            "x": 1,
            "y": 0,
            "z": 5,
            "elements": [
                "astralsorcery:blockblackmarble@3"
            ]
        },
        {
            "x": -1,
            "y": 0,
            "z": 6,
            "elements": [
                "thaumicaugmentation:starfield_glass@2"
            ]
        },
        {
            "x": 1,
            "y": 0,
            "z": 1,
            "elements": [
                "astralsorcery:blockblackmarble@3"
            ]
        },
        {
            "x": -3,
            "y": 2,
            "z": 3,
            "elements": [
                "astralsorcery:blockblackmarble@2"
            ]
        },
        {
            "x": 0,
            "y": 0,
            "z": 3,
            "elements": [
                "roots:chiseled_runed_obsidian@0"
            ]
        },
        {
            "x": -1,
            "y": 0,
            "z": 4,
            "elements": [
                "thaumicaugmentation:starfield_glass@2"
            ]
        },
        {
            "x": 3,
            "y": 0,
            "z": 4,
            "elements": [
                "thaumicaugmentation:starfield_glass@2"
            ]
        },
        {
            "x": 0,
            "y": 1,
            "z": 3,
            "elements": [
                "modularmachinery:blockstarlightproviderinput"
            ]
        },
        {
            "x": 2,
            "y": 0,
            "z": 2,
            "elements": [
                "thaumicaugmentation:starfield_glass@2"
            ]
        },
        {
            "x": 1,
            "y": 0,
            "z": 0,
            "elements": [
                "thaumicaugmentation:starfield_glass@2"
            ]
        },
        {
            "x": -3,
            "y": 0,
            "z": 4,
            "elements": [
                "thaumicaugmentation:starfield_glass@2"
            ]
        },
        {
            "x": -2,
            "y": 0,
            "z": 5,
            "elements": [
                "thaumicaugmentation:starfield_glass@2"
            ]
        },
        {
            "x": 0,
            "y": 0,
            "z": 6,
            "elements": [
                "starlight_laser_hatch"
            ]
        },
        {
            "x": 2,
            "y": 0,
            "z": 5,
            "elements": [
                "thaumicaugmentation:starfield_glass@2"
            ]
        },
        {
            "x": 0,
            "y": 0,
            "z": 1,
            "elements": [
                "astralsorcery:blockblackmarble@3"
            ]
        },
        {
            "x": 3,
            "y": 2,
            "z": 3,
            "elements": [
                "astralsorcery:blockblackmarble@2"
            ]
        },
        {
            "x": 1,
            "y": 0,
            "z": 3,
            "elements": [
                "astralsorcery:blockblackmarble@3"
            ]
        },
        {
            "x": -3,
            "y": 0,
            "z": 3,
            "elements": [
                "starlight_laser_hatch"
            ]
        },
        {
            "x": 0,
            "y": 0,
            "z": 4,
            "elements": [
                "astralsorcery:blockblackmarble@3"
            ]
        },
        {
            "x": -1,
            "y": 0,
            "z": 2,
            "elements": [
                "thaumicaugmentation:starfield_glass@2"
            ]
        },
        {
            "x": 0,
            "y": 1,
            "z": 6,
            "elements": [
                "astralsorcery:blockblackmarble@2"
            ]
        },
        {
            "x": 3,
            "y": 0,
            "z": 2,
            "elements": [
                "thaumicaugmentation:starfield_glass@2"
            ]
        },
        {
            "x": -2,
            "y": 0,
            "z": 0,
            "elements": [
                "thaumicaugmentation:starfield_glass@2"
            ]
        },
        {
            "x": 2,
            "y": 0,
            "z": 0,
            "elements": [
                "thaumicaugmentation:starfield_glass@2"
            ]
        },
        {
            "x": -1,
            "y": 0,
            "z": 1,
            "elements": [
                "astralsorcery:blockblackmarble@3"
            ]
        },
        {
            "x": 0,
            "y": 2,
            "z": 6,
            "elements": [
                "astralsorcery:blockblackmarble@2"
            ]
        },
        {
            "x": 3,
            "y": 1,
            "z": 3,
            "elements": [
                "astralsorcery:blockblackmarble@2"
            ]
        },
        {
            "x": -1,
            "y": 0,
            "z": 5,
            "elements": [
                "astralsorcery:blockblackmarble@3"
            ]
        },
        {
            "x": 1,
            "y": 0,
            "z": 6,
            "elements": [
                "thaumicaugmentation:starfield_glass@2"
            ]
        },
        {
            "x": 0,
            "y": 3,
            "z": 6,
            "elements": [
                "actuallyadditions:block_laser_relay@1"
            ]
        },
        {
            "x": 3,
            "y": 3,
            "z": 3,
            "elements": [
                "actuallyadditions:block_laser_relay@1"
            ]
        },
        {
            "x": 2,
            "y": 0,
            "z": 3,
            "elements": [
                "astralsorcery:blockblackmarble@3"
            ]
        },
        {
            "x": 0,
            "y": 3,
            "z": 0,
            "elements": [
                "actuallyadditions:block_laser_relay@1"
            ]
        },
        {
            "x": -2,
            "y": 0,
            "z": 3,
            "elements": [
                "astralsorcery:blockblackmarble@3"
            ]
        },
        {
            "x": 1,
            "y": 0,
            "z": 4,
            "elements": [
                "thaumicaugmentation:starfield_glass@2"
            ]
        },
        {
            "x": 0,
            "y": 0,
            "z": 2,
            "elements": [
                "astralsorcery:blockblackmarble@3"
            ]
        },
        {
            "x": -1,
            "y": 0,
            "z": 0,
            "elements": [
                "thaumicaugmentation:starfield_glass@2"
            ]
        },
        {
            "x": -2,
            "y": 0,
            "z": 1,
            "elements": [
                "thaumicaugmentation:starfield_glass@2"
            ]
        },
        {
            "x": -3,
            "y": 3,
            "z": 3,
            "elements": [
                "actuallyadditions:block_laser_relay@1"
            ]
        },
        {
            "x": -3,
            "y": 0,
            "z": 2,
            "elements": [
                "thaumicaugmentation:starfield_glass@2"
            ]
        },
        {
            "x": 0,
            "y": 2,
            "z": 0,
            "elements": [
                "astralsorcery:blockblackmarble@2"
            ]
        },
        {
            "x": 0,
            "y": 0,
            "z": 5,
            "elements": [
                "astralsorcery:blockblackmarble@3"
            ]
        },
        {
            "x": -2,
            "y": 0,
            "z": 6,
            "elements": [
                "thaumicaugmentation:starfield_glass@2"
            ]
        },
        {
            "x": 2,
            "y": 0,
            "z": 1,
            "elements": [
                "thaumicaugmentation:starfield_glass@2"
            ]
        },
        {
            "x": 2,
            "y": 0,
            "z": 6,
            "elements": [
                "thaumicaugmentation:starfield_glass@2"
            ]
        },
        {
            "x": 3,
            "y": 0,
            "z": 3,
            "elements": [
                "starlight_laser_hatch"
            ]
        },
        {
            "x": 0,
            "y": 1,
            "z": 0,
            "elements": [
                "astralsorcery:blockblackmarble@2"
            ]
        },
        {
            "x": -1,
            "y": 0,
            "z": 3,
            "elements": [
                "astralsorcery:blockblackmarble@3"
            ]
        },
        {
            "x": -2,
            "y": 0,
            "z": 4,
            "elements": [
                "thaumicaugmentation:starfield_glass@2"
            ]
        },
        {
            "x": 2,
            "y": 0,
            "z": 4,
            "elements": [
                "thaumicaugmentation:starfield_glass@2"
            ]
        },
        {
            "x": 1,
            "y": 0,
            "z": 2,
            "elements": [
                "thaumicaugmentation:starfield_glass@2"
            ]
        },
        {
            "x": 0,
            "y": 3,
            "z": 3,
            "elements": [
                "astralsorcery:blockcollectorcrystal@0"
            ]
        }
    ]
}